2024-07-04 01:56:28,521 Internal Server Error: /news/create/ ERROR D:\Projects\dp4-master\venv\lib\site-packages\django\utils\log.py (<class 'kombu.exceptions.OperationalError'>, OperationalError('Error 10061 connecting to localhost:6379. Подключение не установлено, т.к. конечный компьютер отверг запрос на подключение.'), <traceback object at 0x000001B86C90CC00>)
Traceback (most recent call last):
  File "D:\Projects\dp4-master\venv\lib\site-packages\redis\connection.py", line 707, in connect
    sock = self.retry.call_with_retry(
  File "D:\Projects\dp4-master\venv\lib\site-packages\redis\retry.py", line 46, in call_with_retry
    return do()
  File "D:\Projects\dp4-master\venv\lib\site-packages\redis\connection.py", line 708, in <lambda>
    lambda: self._connect(), lambda error: self.disconnect(error)
  File "D:\Projects\dp4-master\venv\lib\site-packages\redis\connection.py", line 1006, in _connect
    raise err
  File "D:\Projects\dp4-master\venv\lib\site-packages\redis\connection.py", line 994, in _connect
    sock.connect(socket_address)
ConnectionRefusedError: [WinError 10061] Подключение не установлено, т.к. конечный компьютер отверг запрос на подключение

During handling of the above exception, another exception occurred:

Traceback (most recent call last):
  File "D:\Projects\dp4-master\venv\lib\site-packages\celery\backends\redis.py", line 127, in reconnect_on_error
    yield
  File "D:\Projects\dp4-master\venv\lib\site-packages\celery\backends\redis.py", line 177, in _consume_from
    self._pubsub.subscribe(key)
  File "D:\Projects\dp4-master\venv\lib\site-packages\redis\client.py", line 1634, in subscribe
    ret_val = self.execute_command("SUBSCRIBE", *new_channels.keys())
  File "D:\Projects\dp4-master\venv\lib\site-packages\redis\client.py", line 1469, in execute_command
    self.connection = self.connection_pool.get_connection(
  File "D:\Projects\dp4-master\venv\lib\site-packages\redis\connection.py", line 1461, in get_connection
    connection.connect()
  File "D:\Projects\dp4-master\venv\lib\site-packages\redis\connection.py", line 713, in connect
    raise ConnectionError(self._error_message(e))
redis.exceptions.ConnectionError: Error 10061 connecting to localhost:6379. Подключение не установлено, т.к. конечный компьютер отверг запрос на подключение.

During handling of the above exception, another exception occurred:

Traceback (most recent call last):
  File "D:\Projects\dp4-master\venv\lib\site-packages\redis\connection.py", line 707, in connect
    sock = self.retry.call_with_retry(
  File "D:\Projects\dp4-master\venv\lib\site-packages\redis\retry.py", line 46, in call_with_retry
    return do()
  File "D:\Projects\dp4-master\venv\lib\site-packages\redis\connection.py", line 708, in <lambda>
    lambda: self._connect(), lambda error: self.disconnect(error)
  File "D:\Projects\dp4-master\venv\lib\site-packages\redis\connection.py", line 1006, in _connect
    raise err
  File "D:\Projects\dp4-master\venv\lib\site-packages\redis\connection.py", line 994, in _connect
    sock.connect(socket_address)
ConnectionRefusedError: [WinError 10061] Подключение не установлено, т.к. конечный компьютер отверг запрос на подключение

During handling of the above exception, another exception occurred:

Traceback (most recent call last):
  File "D:\Projects\dp4-master\venv\lib\site-packages\kombu\connection.py", line 472, in _reraise_as_library_errors
    yield
  File "D:\Projects\dp4-master\venv\lib\site-packages\celery\app\base.py", line 797, in send_task
    self.backend.on_task_call(P, task_id)
  File "D:\Projects\dp4-master\venv\lib\site-packages\celery\backends\redis.py", line 373, in on_task_call
    self.result_consumer.consume_from(task_id)
  File "D:\Projects\dp4-master\venv\lib\site-packages\celery\backends\redis.py", line 169, in consume_from
    return self.start(task_id)
  File "D:\Projects\dp4-master\venv\lib\site-packages\celery\backends\redis.py", line 147, in start
    self._consume_from(initial_task_id)
  File "D:\Projects\dp4-master\venv\lib\site-packages\celery\backends\redis.py", line 176, in _consume_from
    with self.reconnect_on_error():
  File "C:\Users\sonyc\AppData\Local\Programs\Python\Python310\lib\contextlib.py", line 153, in __exit__
    self.gen.throw(typ, value, traceback)
  File "D:\Projects\dp4-master\venv\lib\site-packages\celery\backends\redis.py", line 130, in reconnect_on_error
    self._ensure(self._reconnect_pubsub, ())
  File "D:\Projects\dp4-master\venv\lib\site-packages\celery\backends\redis.py", line 384, in ensure
    return retry_over_time(
  File "D:\Projects\dp4-master\venv\lib\site-packages\kombu\utils\functional.py", line 318, in retry_over_time
    return fun(*args, **kwargs)
  File "D:\Projects\dp4-master\venv\lib\site-packages\celery\backends\redis.py", line 106, in _reconnect_pubsub
    metas = self.backend.client.mget(self.subscribed_to)
  File "D:\Projects\dp4-master\venv\lib\site-packages\redis\commands\core.py", line 2002, in mget
    return self.execute_command("MGET", *args, **options)
  File "D:\Projects\dp4-master\venv\lib\site-packages\redis\client.py", line 1266, in execute_command
    conn = self.connection or pool.get_connection(command_name, **options)
  File "D:\Projects\dp4-master\venv\lib\site-packages\redis\connection.py", line 1461, in get_connection
    connection.connect()
  File "D:\Projects\dp4-master\venv\lib\site-packages\redis\connection.py", line 713, in connect
    raise ConnectionError(self._error_message(e))
redis.exceptions.ConnectionError: Error 10061 connecting to localhost:6379. Подключение не установлено, т.к. конечный компьютер отверг запрос на подключение.

The above exception was the direct cause of the following exception:

Traceback (most recent call last):
  File "D:\Projects\dp4-master\venv\lib\site-packages\django\core\handlers\exception.py", line 55, in inner
    response = get_response(request)
  File "D:\Projects\dp4-master\venv\lib\site-packages\django\core\handlers\base.py", line 197, in _get_response
    response = wrapped_callback(request, *callback_args, **callback_kwargs)
  File "D:\Projects\dp4-master\venv\lib\site-packages\django\views\generic\base.py", line 104, in view
    return self.dispatch(request, *args, **kwargs)
  File "D:\Projects\dp4-master\venv\lib\site-packages\django\contrib\auth\mixins.py", line 109, in dispatch
    return super().dispatch(request, *args, **kwargs)
  File "D:\Projects\dp4-master\venv\lib\site-packages\django\views\generic\base.py", line 143, in dispatch
    return handler(request, *args, **kwargs)
  File "D:\Projects\dp4-master\venv\lib\site-packages\django\views\generic\edit.py", line 184, in post
    return super().post(request, *args, **kwargs)
  File "D:\Projects\dp4-master\venv\lib\site-packages\django\views\generic\edit.py", line 153, in post
    return self.form_valid(form)
  File "D:\Projects\dp4-master\venv\lib\site-packages\django\views\generic\edit.py", line 135, in form_valid
    self.object = form.save()
  File "D:\Projects\dp4-master\venv\lib\site-packages\django\forms\models.py", line 543, in save
    self._save_m2m()
  File "D:\Projects\dp4-master\venv\lib\site-packages\django\forms\models.py", line 524, in _save_m2m
    f.save_form_data(self.instance, cleaned_data[f.name])
  File "D:\Projects\dp4-master\venv\lib\site-packages\django\db\models\fields\related.py", line 1956, in save_form_data
    getattr(instance, self.attname).set(data)
  File "D:\Projects\dp4-master\venv\lib\site-packages\django\db\models\fields\related_descriptors.py", line 1236, in set
    self.add(*new_objs, through_defaults=through_defaults)
  File "D:\Projects\dp4-master\venv\lib\site-packages\django\db\models\fields\related_descriptors.py", line 1137, in add
    self._add_items(
  File "D:\Projects\dp4-master\venv\lib\site-packages\django\db\models\fields\related_descriptors.py", line 1447, in _add_items
    signals.m2m_changed.send(
  File "D:\Projects\dp4-master\venv\lib\site-packages\django\dispatch\dispatcher.py", line 176, in send
    return [
  File "D:\Projects\dp4-master\venv\lib\site-packages\django\dispatch\dispatcher.py", line 177, in <listcomp>
    (receiver, receiver(signal=self, sender=sender, **named))
  File "D:\Projects\dp4-master\NewsPapers\newapp\signals.py", line 21, in notify_about_new_post
    send_notifications.delay(instance.preview(), instance.pk, instance.title, subscribers)
  File "D:\Projects\dp4-master\venv\lib\site-packages\celery\app\task.py", line 444, in delay
    return self.apply_async(args, kwargs)
  File "D:\Projects\dp4-master\venv\lib\site-packages\celery\app\task.py", line 594, in apply_async
    return app.send_task(
  File "D:\Projects\dp4-master\venv\lib\site-packages\celery\app\base.py", line 795, in send_task
    with P.connection._reraise_as_library_errors():
  File "C:\Users\sonyc\AppData\Local\Programs\Python\Python310\lib\contextlib.py", line 153, in __exit__
    self.gen.throw(typ, value, traceback)
  File "D:\Projects\dp4-master\venv\lib\site-packages\kombu\connection.py", line 476, in _reraise_as_library_errors
    raise ConnectionError(str(exc)) from exc
kombu.exceptions.OperationalError: Error 10061 connecting to localhost:6379. Подключение не установлено, т.к. конечный компьютер отверг запрос на подключение.
